<?xml version='1.0'?>
<robot name="orca4_ign" xmlns:xacro="http://ros.org/wiki/xacro">
    <origin xyz="0 0 0" rpy="0 0 0"/>

    <!-- BlueROV2 thruster reference: http://www.ardusub.com/introduction/features.html -->
    <!-- fluid_density: 1000 -->
    <!-- displaced_mass: 10.05 -->

    <link name="base_link">
      <inertial>
        <origin xyz="0 0 0.011" rpy="0 0 0"/>
        <mass value="10.036"/>
        <inertia ixx="0.09873097998042396" ixy="0.0" ixz="0.0" iyy="0.17756847998042397" iyz="0.0" izz="0.2692441666666667"/>
      </inertial>

      <visual name="base_link_visual">
        <geometry>
          <mesh filename="package://auv_core/meshes/bluerov2.dae" scale = "0.025 0.025 0.025"/>
        </geometry>
      </visual>

      <!-- Collision volume * fluid_density == displaced mass, used by BuoyancyPlugin -->
      <collision name="base_link_collision">
        <origin xyz="0 0 0.06" rpy="0 0 0"/>
        <geometry>
          <box size = "0.457 0.338 0.06506286173008947"/>
        </geometry>
      </collision>

    </link>

    <!-- Hydrodynamics plugin -->
    <gazebo>
    <plugin
        filename="ignition-gazebo-hydrodynamics-system"
        name="ignition::gazebo::systems::Hydrodynamics">
      <link_name>base_link</link_name>
      <water_density>1000</water_density>
      <!-- Added mass: -->
      <xDotU>0</xDotU>
      <yDotV>0</yDotV>
      <zDotW>0</zDotW>
      <kDotP>0</kDotP>
      <mDotQ>0</mDotQ>
      <nDotR>0</nDotR>
      <!-- First order stability derivative: -->
      <xU>0</xU>
      <yV>0</yV>
      <zW>0</zW>
      <kP>0</kP>
      <mQ>0</mQ>
      <nR>0</nR>
      <!-- Second order stability derivative: -->
      <xUabsU>-33.800000000000004</xUabsU>
      <yVabsV>-54.26875</yVabsV>
      <zWabsW>-73.37135</zWabsW>
      <kPabsP>-4.0</kPabsP>
      <mQabsQ>-4.0</mQabsQ>
      <nRabsR>-4.0</nRabsR>
    </plugin>
    </gazebo>

    <link name="thruster1">
      <visual name="thruster_prop_visual">
        <origin xyz="0 0 0" rpy="1.5707963267948966 0 0"/>
        <geometry>
          <mesh filename="package://auv_core/meshes/t200-cw-prop.dae"/>
        </geometry>
      </visual>
      <inertial>
        <mass value="0.002"/>
        <inertia ixx="0.001" ixy="0.0" ixz="0.0" iyy="0.001" iyz="0.0" izz="0.001" />
      </inertial>
    </link>

    <link name="thruster2">
      <origin xyz="0.14 0.092 0" rpy="-1.5707963267948966 1.5707963267948966 -2.356194490192345"/>
      <visual name="thruster_prop_visual">
        <origin xyz="0 0 0" rpy="1.5707963267948966 0 0"/>
        <geometry>
          <mesh filename="package://auv_core/meshes/t200-ccw-prop.dae"/>
        </geometry>
      </visual>
      <inertial>
        <mass value="0.002"/>
        <inertia ixx="0.001" ixy="0.0" ixz="0.0" iyy="0.001" iyz="0.0" izz="0.001" />
      </inertial>
    </link>

    <link name="thruster3">
      <origin xyz="-0.14 -0.092 0" rpy="-1.5707963267948966 1.5707963267948966 0.7853981633974483"/>
      <visual name="thruster_prop_visual">
        <origin xyz="0 0 0" rpy="-1.5707963267948966 0 0"/>
        <geometry>
          <mesh filename="package://auv_core/meshes/t200-ccw-prop.dae"/>
        </geometry>
      </visual>
      <inertial>
        <mass value="0.002"/>
        <inertia ixx="0.001" ixy="0.0" ixz="0.0" iyy="0.001" iyz="0.0" izz="0.001" />
      </inertial>
    </link>

    <link name="thruster4">
      <origin xyz="-0.14 0.092 0" rpy="-1.5707963267948966 1.5707963267948966 2.356194490192345"/>
      <visual name="thruster_prop_visual">
        <origin xyz="0 0 0" rpy="1.5707963267948966 0 0"/>
        <geometry>
          <mesh filename="package://auv_core/meshes/t200-cw-prop.dae"/>
        </geometry>
      </visual>
      <inertial>
        <mass value="0.002"/>
        <inertia ixx="0.001" ixy="0.0" ixz="0.0" iyy="0.001" iyz="0.0" izz="0.001" />
      </inertial>
    </link>

    <link name="thruster5">
      <origin xyz="0 -0.109 0.077" rpy="0 0 0"/>
      <visual name="thruster_prop_visual">
        <origin xyz="0 0 0" rpy="-1.5707963267948966 0 1.5707963267948966"/>
        <geometry>
          <mesh filename="package://auv_core/meshes/t200-ccw-prop.dae"/>
        </geometry>
      </visual>
      <inertial>
        <mass value="0.002"/>
        <inertia ixx="0.001" ixy="0.0" ixz="0.0" iyy="0.001" iyz="0.0" izz="0.001" />
      </inertial>
    </link>

    <link name="thruster6">
      <origin xyz="0 0.109 0.077" rpy="0 0 0"/>
      <visual name="thruster_prop_visual">
        <origin xyz="0 0 0" rpy="1.5707963267948966 0 1.5707963267948966"/>
        <geometry>
          <mesh filename="package://auv_core/meshes/t200-cw-prop.dae"/>
        </geometry>
      </visual>
      <inertial>
        <mass value="0.002"/>
        <inertia ixx="0.001" ixy="0.0" ixz="0.0" iyy="0.001" iyz="0.0" izz="0.001" />
      </inertial>
    </link>


    <joint name="thruster1_joint" type="revolute">
      <parent link = "base_link" />
      <child link = "thruster1" />
      <origin xyz="0.14 -0.092 0" rpy="-1.5707963267948966 1.5707963267948966 -0.7853981633974483"/>
      <axis xyz = "0 0 -1" />
      <limit lower="-1e+12" upper="1e+12" effort="-1" velocity="-1"/>
    </joint>

    <joint name="thruster2_joint" type="revolute">
      <parent link = "base_link" />
      <child link = "thruster2" />
      <origin xyz="0.14 0.092 0" rpy="-1.5707963267948966 1.5707963267948966 -2.356194490192345"/>
      <axis xyz = "0 0 -1" />
      <limit lower="-1e+12" upper="1e+12" effort="-1" velocity="-1"/>
    </joint>

    <joint name="thruster3_joint" type="revolute">
      <parent link = "base_link" />
      <child link = "thruster3" />
      <origin xyz="-0.14 -0.092 0" rpy="-1.5707963267948966 1.5707963267948966 0.7853981633974483"/>
      <axis xyz = "0 0 -1" />
      <limit lower="-1e+12" upper="1e+12" effort="-1" velocity="-1"/>
    </joint>

    <joint name="thruster4_joint" type="revolute">
      <parent link = "base_link" />
      <child link = "thruster4" />
      <origin xyz="-0.14 0.092 0" rpy="-1.5707963267948966 1.5707963267948966 2.356194490192345"/>
      <axis xyz = "0 0 -1" />
      <limit lower="-1e+12" upper="1e+12" effort="-1" velocity="-1"/>
    </joint>

    <joint name="thruster5_joint" type="revolute">
      <parent link = "base_link" />
      <child link = "thruster5" />
      <origin xyz="0 -0.109 0.077" rpy="0 0 0"/>
      <axis xyz = "0 0 -1" />
      <limit lower="-1e+12" upper="1e+12" effort="-1" velocity="-1"/>
    </joint>

    <joint name="thruster6_joint" type="revolute">
      <parent link = "base_link" />
      <child link = "thruster6" />
      <origin xyz="0 0.109 0.077" rpy="0 0 0"/>
      <axis xyz = "0 0 -1" />
      <limit lower="-1e+12" upper="1e+12" effort="-1" velocity="-1"/>
    </joint>

    <gazebo>
    <plugin
        filename="ignition-gazebo-thruster-system"
        name="ignition::gazebo::systems::Thruster">
      <namespace>orca4_ign</namespace>
      <joint_name>thruster1_joint</joint_name>
      <thrust_coefficient>0.02</thrust_coefficient> 
      <topic>/model/orca4_ign/joint/thruster1_joint/cmd_vel</topic>
      <fluid_density>1000</fluid_density>
      <propeller_diameter>0.1</propeller_diameter>
      <velocity_control>true</velocity_control>
      <use_angvel_cmd>true</use_angvel_cmd>
      <max_thrust_cmd>300</max_thrust_cmd> 
      <min_thrust_cmd>-300</min_thrust_cmd>
    </plugin>
    </gazebo>

    <gazebo>
    <plugin
        filename="ignition-gazebo-thruster-system"
        name="ignition::gazebo::systems::Thruster">
      <namespace>orca4_ign</namespace>
      <joint_name>thruster2_joint</joint_name>
      <thrust_coefficient>0.02</thrust_coefficient>
      <topic>/model/orca4_ign/joint/thruster2_joint/cmd_vel</topic>
      <fluid_density>1000</fluid_density>
      <propeller_diameter>0.1</propeller_diameter>
      <velocity_control>true</velocity_control>
      <use_angvel_cmd>true</use_angvel_cmd>
      <max_thrust_cmd>300</max_thrust_cmd>
      <min_thrust_cmd>-300</min_thrust_cmd>
    </plugin>
    </gazebo>

    <gazebo>
    <plugin
        filename="ignition-gazebo-thruster-system"
        name="ignition::gazebo::systems::Thruster">
      <namespace>orca4_ign</namespace>
      <joint_name>thruster3_joint</joint_name>
      <thrust_coefficient>-0.02</thrust_coefficient>
      <topic>/model/orca4_ign/joint/thruster3_joint/cmd_vel</topic>
      <fluid_density>1000</fluid_density>
      <propeller_diameter>0.1</propeller_diameter>
      <velocity_control>true</velocity_control>
      <use_angvel_cmd>true</use_angvel_cmd>
      <max_thrust_cmd>300</max_thrust_cmd>
      <min_thrust_cmd>-300</min_thrust_cmd>
    </plugin>
    </gazebo>

    <gazebo>
    <plugin
        filename="ignition-gazebo-thruster-system"
        name="ignition::gazebo::systems::Thruster">
      <namespace>orca4_ign</namespace>
      <joint_name>thruster4_joint</joint_name>
      <thrust_coefficient>-0.02</thrust_coefficient>
      <topic>/model/orca4_ign/joint/thruster4_joint/cmd_vel</topic>
      <fluid_density>1000</fluid_density>
      <propeller_diameter>0.1</propeller_diameter>
      <velocity_control>true</velocity_control>
      <use_angvel_cmd>true</use_angvel_cmd>
      <max_thrust_cmd>300</max_thrust_cmd>
      <min_thrust_cmd>-300</min_thrust_cmd>
    </plugin>
    </gazebo>

    <gazebo>
    <plugin
        filename="ignition-gazebo-thruster-system"
        name="ignition::gazebo::systems::Thruster">
      <namespace>orca4_ign</namespace>
      <joint_name>thruster5_joint</joint_name>
      <thrust_coefficient>0.02</thrust_coefficient>
      <topic>/model/orca4_ign/joint/thruster5_joint/cmd_vel</topic>
      <fluid_density>1000</fluid_density>
      <propeller_diameter>0.1</propeller_diameter>
      <velocity_control>true</velocity_control>
      <use_angvel_cmd>true</use_angvel_cmd>
      <max_thrust_cmd>300</max_thrust_cmd>
      <min_thrust_cmd>-300</min_thrust_cmd>
    </plugin>
    </gazebo>

    <gazebo>
    <plugin
        filename="ignition-gazebo-thruster-system"
        name="ignition::gazebo::systems::Thruster">
      <namespace>orca4_ign</namespace>
      <joint_name>thruster6_joint</joint_name>
      <thrust_coefficient>-0.02</thrust_coefficient>
      <topic>/model/orca4_ign/joint/thruster6_joint/cmd_vel</topic>
      <fluid_density>1000</fluid_density>
      <propeller_diameter>0.1</propeller_diameter>
      <velocity_control>true</velocity_control>
      <use_angvel_cmd>true</use_angvel_cmd>
      <max_thrust_cmd>300</max_thrust_cmd>
      <min_thrust_cmd>-300</min_thrust_cmd>
    </plugin>
    </gazebo>

    <!-- Left camera link -->
    <link name="left_camera_link">
      <origin xyz = "0.15 0.2 -0.06749999999999999" rpy= "0 0 0"/>
      <visual name="left_camera_tube">
        <transparency>0.5</transparency>
        <geometry>
          <cylinder length = "0.135" radius = "0.0275" />
        </geometry>
      </visual>
      <inertial>
        <mass value="0.001"/>
        <inertia ixx="0.001" ixy="0.0" ixz="0.0" iyy="0.001" iyz="0.0" izz="0.001" />
      </inertial>
    </link>

    <!-- Attach left_camera_link to base_link -->
    <joint name="left_camera_joint" type="fixed">
      <parent link = "base_link" />
      <child link = "left_camera_link" />
      <origin xyz = "0.15 0.2 -0.0675" rpy= "0 0 1.5707963267948966"/>
    </joint>

    <gazebo reference="left_camera_link">
      <sensor name="left_camera" type="camera">
        <origin xyz = "0.15 0.2 -0.0675" rpy = "0 0 1.5707963267948966" />
          <camera>
             <horizontal_fov>1.4</horizontal_fov>
          <image>
            <width>800</width>
            <height>600</height>
          </image>
          <clip>
            <near>0.2</near>
            <far>4</far>
          </clip>
          <optical_frame_id>left_camera_link</optical_frame_id>
        </camera>
        <always_on>1</always_on>
        <update_rate>5</update_rate>
        <visualize>true</visualize>
        <topic>stereo_left</topic>
      </sensor>
      </gazebo>

    <!-- Right camera link -->
    <link name="right_camera_link">
      <origin xyz = "0.15 -0.2 -0.0675" rpy = "0 0 0" />
      <visual name="right_camera_tube">
        <transparency>0.5</transparency>
        <geometry>
          <cylinder length = "0.135" radius = "0.0275" />
        </geometry>
      </visual>
      <inertial>
        <mass value="0.001"/>
        <inertia ixx="0.001" ixy="0.0" ixz="0.0" iyy="0.001" iyz="0.0" izz="0.001" />
      </inertial>
    </link>

    <!-- Attach right_camera_link to base_link -->
    <joint name="right_camera_joint" type="fixed">
      <parent link = "base_link" />
      <child link = "right_camera_link" />
      <origin xyz = "0.15 -0.2 -0.0675" rpy = "0 0 -1.5707963267948966" />
    </joint>

    <gazebo reference="right_camera_link">
    <sensor name="right_camera" type="camera">
        <origin xyz = "0.15 -0.2 -0.0675" rpy = "0 0 -1.5707963267948966" />
        <camera>
          <horizontal_fov>1.4</horizontal_fov>
          <image>
            <width>800</width>
            <height>600</height>
          </image>
          <clip>
            <near>0.2</near>
            <far>4</far>
          </clip>
          <optical_frame_id>right_camera_link</optical_frame_id>
        </camera>
        <always_on>1</always_on>
        <update_rate>5</update_rate>
        <visualize>true</visualize>
        <topic>stereo_right</topic>
      </sensor>
      </gazebo>

    <!-- Publish the ground-truth pose for rviz -->
    <!-- <plugin
        filename="ignition-gazebo-odometry-publisher-system"
        name="ignition::gazebo::systems::OdometryPublisher">
      <odom_frame>map</odom_frame>
      <robot_base_frame>orca4_ign</robot_base_frame>
      <dimensions>3</dimensions>
    </plugin> -->

    <!-- Forward Camera Link for Gate Detection -->
    <link name="forward_camera_link">
      <origin xyz="0.2 0 0" rpy="0 0 0"/>
      <visual name="forward_camera_visual">
        <transparency>0.5</transparency>
        <geometry>
          <cylinder length="0.05" radius="0.02"/>
        </geometry>
      </visual>
      <inertial>
        <mass value="0.001"/>
        <inertia ixx="0.001" ixy="0.0" ixz="0.0" iyy="0.001" iyz="0.0" izz="0.001"/>
      </inertial>
    </link>

    <!-- Attach forward_camera_link to base_link -->
    <joint name="forward_camera_joint" type="fixed">
      <parent link="base_link"/>
      <child link="forward_camera_link"/>
      <origin xyz="0.2 0 0" rpy="0 0 0"/>
    </joint>

    <gazebo reference="forward_camera_link">
      <sensor name="forward_camera" type="camera">
        <origin xyz="0.2 0 0" rpy="0 0 0"/>
        <camera>
          <horizontal_fov>1.4</horizontal_fov>
          <image>
            <width>800</width>
            <height>600</height>
          </image>
          <clip>
            <near>0.2</near>
            <far>10</far>
          </clip>
          <optical_frame_id>forward_camera_link</optical_frame_id>
        </camera>
        <always_on>1</always_on>
        <update_rate>30</update_rate>
        <visualize>true</visualize>
        <topic>camera_forward</topic>
      </sensor>
    </gazebo>

    <!-- Downward Camera Link (for optical flow) -->
    <link name="downward_camera_link">
      <origin xyz="0 0 -0.1" rpy="0 1.5707963267948966 0"/>
      <visual name="downward_camera_visual">
        <transparency>0.5</transparency>
        <geometry>
          <cylinder length="0.05" radius="0.02"/>
        </geometry>
      </visual>
      <inertial>
        <mass value="0.001"/>
        <inertia ixx="0.001" ixy="0.0" ixz="0.0" iyy="0.001" iyz="0.0" izz="0.001"/>
      </inertial>
    </link>

    <!-- Attach downward_camera_link to base_link -->
    <joint name="downward_camera_joint" type="fixed">
      <parent link="base_link"/>
      <child link="downward_camera_link"/>
      <origin xyz="0 0 -0.1" rpy="0 1.5707963267948966 0"/>
    </joint>

    <gazebo reference="downward_camera_link">
      <sensor name="downward_camera" type="camera">
        <origin xyz="0 0 -0.1" rpy="0 1.5707963267948966 0"/>
        <camera>
          <horizontal_fov>1.4</horizontal_fov>
          <image>
            <width>800</width>
            <height>600</height>
          </image>
          <clip>
            <near>0.1</near>
            <far>5</far>
          </clip>
          <optical_frame_id>downward_camera_link</optical_frame_id>
        </camera>
        <always_on>1</always_on>
        <update_rate>30</update_rate>
        <visualize>true</visualize>
        <topic>camera_down</topic>
      </sensor>
    </gazebo>

    <gazebo>
    <plugin
    filename="ignition-gazebo-odometry-publisher-system"
    name="ignition::gazebo::systems::OdometryPublisher">
    <link_name>base_link</link_name>  <!-- Use your main body link -->
    <odom_publish_topic>/odom</odom_publish_topic> <!-- Optional -->
    <frame_id>odom</frame_id>
    <child_frame_id>base_link</child_frame_id>
    <publish_tf>true</publish_tf>
    <use_world_coordinates>true</use_world_coordinates>
    <covariance> <!-- Optional -->
      0.01 0 0 0 0 0
      0 0.01 0 0 0 0
      0 0 0.01 0 0 0
      0 0 0 0.01 0 0
      0 0 0 0 0.01 0
      0 0 0 0 0 0.01
    </covariance>
  </plugin>
  </gazebo>

    <link name="imu_link">
    <visual>
      <geometry>
        <box size="0.01 0.01 0.01"/>
      </geometry>
    </visual>

    <collision>
      <geometry>
        <box size="0.01 0.01 0.01"/>
      </geometry>
    </collision>

    <inertial>
      <origin xyz="0 0 0" rpy="0 0 0"/>
      <mass value="0.001"/>
      <inertia ixx="0.000001" ixy="0" ixz="0" iyy="0.000001" iyz="0" izz="0.000001"/>
    </inertial>
  </link>

  <joint name="imu_joint" type="fixed">
    <parent link="base_link"/>
    <child link="imu_link"/>
    <origin xyz="0 0 0.01" rpy="0 0 0"/>
  </joint>

  <gazebo reference="imu_link">
    <sensor name="imu_sensor" type="imu">
      <always_on>true</always_on>
      <update_rate>100</update_rate>
      <visualize>true</visualize>
      <topic>/imu/data</topic>
      <plugin filename="ignition-gazebo-imu-system" name="ignition::gazebo::systems::Imu">
      </plugin>
      <imu>
        <angular_velocity>
          <x>
            <noise type="gaussian">
              <mean>0.0</mean>
              <stddev>2e-4</stddev>
              <bias_mean>0.0000075</bias_mean>
              <bias_stddev>0.0000008</bias_stddev>
            </noise>
          </x>
          <y>
            <noise type="gaussian">
              <mean>0.0</mean>
              <stddev>2e-4</stddev>
              <bias_mean>0.0000075</bias_mean>
              <bias_stddev>0.0000008</bias_stddev>
            </noise>
          </y>
          <z>
            <noise type="gaussian">
              <mean>0.0</mean>
              <stddev>2e-4</stddev>
              <bias_mean>0.0000075</bias_mean>
              <bias_stddev>0.0000008</bias_stddev>
            </noise>
          </z>
        </angular_velocity>
        <linear_acceleration>
          <x>
            <noise type="gaussian">
              <mean>0.0</mean>
              <stddev>1.7e-2</stddev>
              <bias_mean>0.1</bias_mean>
              <bias_stddev>0.001</bias_stddev>
            </noise>
          </x>
          <y>
            <noise type="gaussian">
              <mean>0.0</mean>
              <stddev>1.7e-2</stddev>
              <bias_mean>0.1</bias_mean>
              <bias_stddev>0.001</bias_stddev>
            </noise>
          </y>
          <z>
            <noise type="gaussian">
              <mean>0.0</mean>
              <stddev>1.7e-2</stddev>
              <bias_mean>0.1</bias_mean>
              <bias_stddev>0.001</bias_stddev>
            </noise>
          </z>
        </linear_acceleration>
      </imu>
    </sensor>
  </gazebo>

</robot>