<?xml version='1.0'?>
<robot name="orca4_ign" xmlns:xacro="http://ros.org/wiki/xacro">
    <origin xyz="0 0 0" rpy="0 0 0"/>

    <!-- BlueROV2 thruster reference: http://www.ardusub.com/introduction/features.html -->
    <!-- fluid_density: 1000 -->
    <!-- displaced_mass: 10.05 -->

    <link name="base_link">
      <inertial>
        <origin xyz="0 0 0.011" rpy="0 0 0"/>
        <mass value="10.036"/>
        <inertia ixx="0.09873097998042396" ixy="0.0" ixz="0.0" iyy="0.17756847998042397" iyz="0.0" izz="0.2692441666666667"/>
      </inertial>

      <visual name="base_link_visual">
        <geometry>
          <!-- FIXED: Correct mesh path -->
          <mesh filename="package://auv_core/meshes/bluerov2.dae" scale="0.025 0.025 0.025"/>
        </geometry>
      </visual>

      <!-- Collision volume * fluid_density == displaced mass, used by BuoyancyPlugin -->
      <collision name="base_link_collision">
        <origin xyz="0 0 0.06" rpy="0 0 0"/>
        <geometry>
          <box size="0.457 0.338 0.06506286173008947"/>
        </geometry>
      </collision>

    </link>

    <!-- Hydrodynamics plugin -->
    <gazebo>
    <plugin
        filename="ignition-gazebo-hydrodynamics-system"
        name="ignition::gazebo::systems::Hydrodynamics">
      <link_name>base_link</link_name>
      <water_density>1000</water_density>
      <!-- Added mass: -->
      <xDotU>0</xDotU>
      <yDotV>0</yDotV>
      <zDotW>0</zDotW>
      <kDotP>0</kDotP>
      <mDotQ>0</mDotQ>
      <nDotR>0</nDotR>
      <!-- First order stability derivative: -->
      <xU>0</xU>
      <yV>0</yV>
      <zW>0</zW>
      <kP>0</kP>
      <mQ>0</mQ>
      <nR>0</nR>
      <!-- Second order stability derivative: -->
      <xUabsU>-33.800000000000004</xUabsU>
      <yVabsV>-54.26875</yVabsV>
      <zWabsW>-73.37135</zWabsW>
      <kPabsP>-4.0</kPabsP>
      <mQabsQ>-4.0</mQabsQ>
      <nRabsR>-4.0</nRabsR>
    </plugin>
    </gazebo>

    <!-- ========== THRUSTER LINKS ========== -->
    <link name="thruster1">
      <visual name="thruster_prop_visual">
        <origin xyz="0 0 0" rpy="1.5707963267948966 0 0"/>
        <geometry>
          <mesh filename="package://auv_core/meshes/t200-cw-prop.dae"/>
        </geometry>
      </visual>
      <inertial>
        <mass value="0.002"/>
        <inertia ixx="0.001" ixy="0.0" ixz="0.0" iyy="0.001" iyz="0.0" izz="0.001" />
      </inertial>
    </link>

    <link name="thruster2">
      <visual name="thruster_prop_visual">
        <origin xyz="0 0 0" rpy="1.5707963267948966 0 0"/>
        <geometry>
          <mesh filename="package://auv_core/meshes/t200-ccw-prop.dae"/>
        </geometry>
      </visual>
      <inertial>
        <mass value="0.002"/>
        <inertia ixx="0.001" ixy="0.0" ixz="0.0" iyy="0.001" iyz="0.0" izz="0.001" />
      </inertial>
    </link>

    <link name="thruster3">
      <visual name="thruster_prop_visual">
        <origin xyz="0 0 0" rpy="-1.5707963267948966 0 0"/>
        <geometry>
          <mesh filename="package://auv_core/meshes/t200-ccw-prop.dae"/>
        </geometry>
      </visual>
      <inertial>
        <mass value="0.002"/>
        <inertia ixx="0.001" ixy="0.0" ixz="0.0" iyy="0.001" iyz="0.0" izz="0.001" />
      </inertial>
    </link>

    <link name="thruster4">
      <visual name="thruster_prop_visual">
        <origin xyz="0 0 0" rpy="1.5707963267948966 0 0"/>
        <geometry>
          <mesh filename="package://auv_core/meshes/t200-cw-prop.dae"/>
        </geometry>
      </visual>
      <inertial>
        <mass value="0.002"/>
        <inertia ixx="0.001" ixy="0.0" ixz="0.0" iyy="0.001" iyz="0.0" izz="0.001" />
      </inertial>
    </link>

    <link name="thruster5">
      <visual name="thruster_prop_visual">
        <origin xyz="0 0 0" rpy="-1.5707963267948966 0 1.5707963267948966"/>
        <geometry>
          <mesh filename="package://auv_core/meshes/t200-ccw-prop.dae"/>
        </geometry>
      </visual>
      <inertial>
        <mass value="0.002"/>
        <inertia ixx="0.001" ixy="0.0" ixz="0.0" iyy="0.001" iyz="0.0" izz="0.001" />
      </inertial>
    </link>

    <link name="thruster6">
      <visual name="thruster_prop_visual">
        <origin xyz="0 0 0" rpy="1.5707963267948966 0 1.5707963267948966"/>
        <geometry>
          <mesh filename="package://auv_core/meshes/t200-cw-prop.dae"/>
        </geometry>
      </visual>
      <inertial>
        <mass value="0.002"/>
        <inertia ixx="0.001" ixy="0.0" ixz="0.0" iyy="0.001" iyz="0.0" izz="0.001" />
      </inertial>
    </link>

    <!-- ========== THRUSTER JOINTS ========== -->
    <joint name="thruster1_joint" type="revolute">
      <parent link="base_link" />
      <child link="thruster1" />
      <origin xyz="0.14 -0.092 0" rpy="-1.5707963267948966 1.5707963267948966 -0.7853981633974483"/>
      <axis xyz="0 0 -1" />
      <limit lower="-1e+12" upper="1e+12" effort="-1" velocity="-1"/>
    </joint>

    <joint name="thruster2_joint" type="revolute">
      <parent link="base_link" />
      <child link="thruster2" />
      <origin xyz="0.14 0.092 0" rpy="-1.5707963267948966 1.5707963267948966 -2.356194490192345"/>
      <axis xyz="0 0 -1" />
      <limit lower="-1e+12" upper="1e+12" effort="-1" velocity="-1"/>
    </joint>

    <joint name="thruster3_joint" type="revolute">
      <parent link="base_link" />
      <child link="thruster3" />
      <origin xyz="-0.14 -0.092 0" rpy="-1.5707963267948966 1.5707963267948966 0.7853981633974483"/>
      <axis xyz="0 0 -1" />
      <limit lower="-1e+12" upper="1e+12" effort="-1" velocity="-1"/>
    </joint>

    <joint name="thruster4_joint" type="revolute">
      <parent link="base_link" />
      <child link="thruster4" />
      <origin xyz="-0.14 0.092 0" rpy="-1.5707963267948966 1.5707963267948966 2.356194490192345"/>
      <axis xyz="0 0 -1" />
      <limit lower="-1e+12" upper="1e+12" effort="-1" velocity="-1"/>
    </joint>

    <joint name="thruster5_joint" type="revolute">
      <parent link="base_link" />
      <child link="thruster5" />
      <origin xyz="0 -0.109 0.077" rpy="0 0 0"/>
      <axis xyz="0 0 -1" />
      <limit lower="-1e+12" upper="1e+12" effort="-1" velocity="-1"/>
    </joint>

    <joint name="thruster6_joint" type="revolute">
      <parent link="base_link" />
      <child link="thruster6" />
      <origin xyz="0 0.109 0.077" rpy="0 0 0"/>
      <axis xyz="0 0 -1" />
      <limit lower="-1e+12" upper="1e+12" effort="-1" velocity="-1"/>
    </joint>

    <!-- ========== THRUSTER PLUGINS (FIXED) ========== -->
    <gazebo>
    <plugin
        filename="ignition-gazebo-thruster-system"
        name="ignition::gazebo::systems::Thruster">
      <namespace>orca4_ign</namespace>
      <joint_name>thruster1_joint</joint_name>
      <thrust_coefficient>0.2</thrust_coefficient>
      <topic>/model/orca4_ign/joint/thruster1_joint/cmd_vel</topic>
      <fluid_density>1000</fluid_density>
      <propeller_diameter>0.1</propeller_diameter>
      <velocity_control>true</velocity_control>
      <use_angvel_cmd>true</use_angvel_cmd>
      <max_thrust_cmd>300</max_thrust_cmd>
      <min_thrust_cmd>-300</min_thrust_cmd>
    </plugin>
    </gazebo>

    <gazebo>
    <plugin
        filename="ignition-gazebo-thruster-system"
        name="ignition::gazebo::systems::Thruster">
      <namespace>orca4_ign</namespace>
      <joint_name>thruster2_joint</joint_name>
      <thrust_coefficient>0.2</thrust_coefficient>
      <topic>/model/orca4_ign/joint/thruster2_joint/cmd_vel</topic>
      <fluid_density>1000</fluid_density>
      <propeller_diameter>0.1</propeller_diameter>
      <velocity_control>true</velocity_control>
      <use_angvel_cmd>true</use_angvel_cmd>
      <max_thrust_cmd>300</max_thrust_cmd>
      <min_thrust_cmd>-300</min_thrust_cmd>
    </plugin>
    </gazebo>

    <gazebo>
    <plugin
        filename="ignition-gazebo-thruster-system"
        name="ignition::gazebo::systems::Thruster">
      <namespace>orca4_ign</namespace>
      <joint_name>thruster3_joint</joint_name>
      <thrust_coefficient>-0.2</thrust_coefficient>
      <topic>/model/orca4_ign/joint/thruster3_joint/cmd_vel</topic>
      <fluid_density>1000</fluid_density>
      <propeller_diameter>0.1</propeller_diameter>
      <velocity_control>true</velocity_control>
      <use_angvel_cmd>true</use_angvel_cmd>
      <max_thrust_cmd>300</max_thrust_cmd>
      <min_thrust_cmd>-300</min_thrust_cmd>
    </plugin>
    </gazebo>

    <gazebo>
    <plugin
        filename="ignition-gazebo-thruster-system"
        name="ignition::gazebo::systems::Thruster">
      <namespace>orca4_ign</namespace>
      <joint_name>thruster4_joint</joint_name>
      <thrust_coefficient>-0.2</thrust_coefficient>
      <topic>/model/orca4_ign/joint/thruster4_joint/cmd_vel</topic>
      <fluid_density>1000</fluid_density>
      <propeller_diameter>0.1</propeller_diameter>
      <velocity_control>true</velocity_control>
      <use_angvel_cmd>true</use_angvel_cmd>
      <max_thrust_cmd>300</max_thrust_cmd>
      <min_thrust_cmd>-300</min_thrust_cmd>
    </plugin>
    </gazebo>

    <gazebo>
    <plugin
        filename="ignition-gazebo-thruster-system"
        name="ignition::gazebo::systems::Thruster">
      <namespace>orca4_ign</namespace>
      <joint_name>thruster5_joint</joint_name>
      <thrust_coefficient>0.3</thrust_coefficient>
      <topic>/model/orca4_ign/joint/thruster5_joint/cmd_vel</topic>
      <fluid_density>1000</fluid_density>
      <propeller_diameter>0.1</propeller_diameter>
      <velocity_control>true</velocity_control>
      <use_angvel_cmd>true</use_angvel_cmd>
      <max_thrust_cmd>300</max_thrust_cmd>
      <min_thrust_cmd>-300</min_thrust_cmd>
    </plugin>
    </gazebo>

    <gazebo>
    <plugin
        filename="ignition-gazebo-thruster-system"
        name="ignition::gazebo::systems::Thruster">
      <namespace>orca4_ign</namespace>
      <joint_name>thruster6_joint</joint_name>
      <thrust_coefficient>0.3</thrust_coefficient>
      <topic>/model/orca4_ign/joint/thruster6_joint/cmd_vel</topic>
      <fluid_density>1000</fluid_density>
      <propeller_diameter>0.1</propeller_diameter>
      <velocity_control>true</velocity_control>
      <use_angvel_cmd>true</use_angvel_cmd>
      <max_thrust_cmd>300</max_thrust_cmd>
      <min_thrust_cmd>-300</min_thrust_cmd>
    </plugin>
    </gazebo>

    <!-- ========== IMU LINK ========== -->
    <link name="imu_link">
      <visual name="imu_visual">
        <geometry>
          <box size="0.01 0.01 0.01"/>
        </geometry>
      </visual>
      <collision name="imu_collision">
        <geometry>
          <box size="0.01 0.01 0.01"/>
        </geometry>
      </collision>
      <inertial>
        <origin xyz="0 0 0" rpy="0 0 0"/>
        <mass value="0.001"/>
        <inertia ixx="0.000001" ixy="0" ixz="0" iyy="0.000001" iyz="0" izz="0.000001"/>
      </inertial>
    </link>

    <joint name="imu_joint" type="fixed">
      <parent link="base_link"/>
      <child link="imu_link"/>
      <origin xyz="0 0 0.01" rpy="0 0 0"/>
    </joint>

    <gazebo reference="imu_link">
      <sensor name="imu_sensor" type="imu">
        <always_on>true</always_on>
        <update_rate>100</update_rate>
        <visualize>true</visualize>
        <topic>/imu/data</topic>
        <plugin filename="ignition-gazebo-imu-system" name="ignition::gazebo::systems::Imu">
        </plugin>
        <imu>
          <angular_velocity>
            <x>
              <noise type="gaussian">
                <mean>0.0</mean>
                <stddev>2e-4</stddev>
                <bias_mean>0.0000075</bias_mean>
                <bias_stddev>0.0000008</bias_stddev>
              </noise>
            </x>
            <y>
              <noise type="gaussian">
                <mean>0.0</mean>
                <stddev>2e-4</stddev>
                <bias_mean>0.0000075</bias_mean>
                <bias_stddev>0.0000008</bias_stddev>
              </noise>
            </y>
            <z>
              <noise type="gaussian">
                <mean>0.0</mean>
                <stddev>2e-4</stddev>
                <bias_mean>0.0000075</bias_mean>
                <bias_stddev>0.0000008</bias_stddev>
              </noise>
            </z>
          </angular_velocity>
          <linear_acceleration>
            <x>
              <noise type="gaussian">
                <mean>0.0</mean>
                <stddev>1.7e-2</stddev>
                <bias_mean>0.1</bias_mean>
                <bias_stddev>0.001</bias_stddev>
              </noise>
            </x>
            <y>
              <noise type="gaussian">
                <mean>0.0</mean>
                <stddev>1.7e-2</stddev>
                <bias_mean>0.1</bias_mean>
                <bias_stddev>0.001</bias_stddev>
              </noise>
            </y>
            <z>
              <noise type="gaussian">
                <mean>0.0</mean>
                <stddev>1.7e-2</stddev>
                <bias_mean>0.1</bias_mean>
                <bias_stddev>0.001</bias_stddev>
              </noise>
            </z>
          </linear_acceleration>
        </imu>
      </sensor>
    </gazebo>

    <!-- ========== FORWARD CAMERA (For Gate Detection) ========== -->
    <link name="forward_camera_link">
      <visual name="forward_camera_visual">
        <geometry>
          <cylinder length="0.05" radius="0.02"/>
        </geometry>
        <material name="camera_grey">
          <color rgba="0.5 0.5 0.5 0.8"/>
        </material>
      </visual>
      <inertial>
        <mass value="0.001"/>
        <inertia ixx="0.001" ixy="0.0" ixz="0.0" iyy="0.001" iyz="0.0" izz="0.001"/>
      </inertial>
    </link>

    <joint name="forward_camera_joint" type="fixed">
      <parent link="base_link"/>
      <child link="forward_camera_link"/>
      <origin xyz="0.2 0 0" rpy="0 0 0"/>
    </joint>

    <gazebo reference="forward_camera_link">
      <sensor name="forward_camera" type="camera">
        <camera>
          <horizontal_fov>1.4</horizontal_fov>
          <image>
            <width>800</width>
            <height>600</height>
          </image>
          <clip>
            <near>0.2</near>
            <far>10</far>
          </clip>
        </camera>
        <always_on>1</always_on>
        <update_rate>30</update_rate>
        <visualize>true</visualize>
        <topic>camera_forward</topic>
      </sensor>
    </gazebo>

    <!-- ========== ODOMETRY PUBLISHER ========== -->
    <gazebo>
      <plugin
        filename="ignition-gazebo-odometry-publisher-system"
        name="ignition::gazebo::systems::OdometryPublisher">
        <odom_publish_frequency>30</odom_publish_frequency>
        <odom_frame>odom</odom_frame>
        <robot_base_frame>base_link</robot_base_frame>
      </plugin>
    </gazebo>

</robot>